<?xml version="1.0"?>
<!--
  Development of this module has been funded by the Monterey Bay Aquarium
  Research Institute (MBARI) and the David and Lucile Packard Foundation
-->
<sdf version="1.6">
  <model name="tethys">
    <!-- Body -->
    <link name="base_link">
      <inertial>
        <!-- to offset battery CoM before getting real parameters for vehicle without battery -->
        <pose>@calculated</pose>
        <!-- 146.5671 subtracted by battery mass -->
        <mass>@calculated</mass>
        <!--<mass>146.5671</mass>-->
        <!-- TODO: Get inertial matrix of base link WITHOUT battery -->
        <inertia>
          <ixx>3.000000</ixx>
          <ixy>0</ixy>
          <ixz>0</ixz>
          <iyy>41.980233</iyy>
          <iyz>0</iyz>
          <izz>41.980233</izz>

        </inertia>
      </inertial>

      <collision name="main_body_buoyancy">
        @calculated
      </collision>

      <visual name="visual">
        <geometry>
          <mesh>
            <uri>meshes/tethys.dae</uri>
            <submesh>
              <name>Body</name>
              <center>false</center>
            </submesh>
          </mesh>
        </geometry>
        <material>
          <diffuse>1.0 1.0 1.0 1.0</diffuse>
          <specular>1.0 1.0 1.0 1.0</specular>
          <pbr>
            <metal>
              <albedo_map>materials/textures/Tethys_Albedo.png</albedo_map>
              <normal_map>materials/textures/Tethys_Normal.png</normal_map>
              <metalness_map>materials/textures/Tethys_Metalness.png</metalness_map>
              <roughness_map>materials/textures/Tethys_Roughness.png</roughness_map>
            </metal>
          </pbr>
          <script>
            <uri>materials/scripts/</uri>
            <uri>materials/textures/</uri>
            <name>tethys/Tethys_Diffuse</name>
          </script>
        </material>
      </visual>
    </link>

    <!-- Horizontal fins -->
    <link name="horizontal_fins">
      <pose>1.05 0 0 0 0 0</pose>
      <inertial>
        <mass>0.2</mass>
        <inertia>
          <ixx>0.0007924568755</ixx>
          <ixy>-0.0000000002674</ixy>
          <ixz>0.0003978158176</ixz>
          <iyy>0.0010546736475</iyy>
          <iyz>-0.0000000006729</iyz>
          <izz>0.0002633558262</izz>
        </inertia>
      </inertial>

      <collision name="horizontal_fins_buoyancy">
        @neutral_buoyancy
      </collision>

      <visual name= "visual">
        <pose>-1.05 0 0 0 0 0</pose>
        <geometry>
          <mesh>
            <uri>meshes/tethys.dae</uri>
            <submesh>
              <name>Fins_Horizontal</name>
              <center>false</center>
            </submesh>
          </mesh>
        </geometry>
        <material>
          <diffuse>1.0 1.0 1.0</diffuse>
          <specular>1.0 1.0 1.0</specular>
          <pbr>
            <metal>
              <albedo_map>materials/textures/Tethys_Albedo.png</albedo_map>
              <normal_map>materials/textures/Tethys_Normal.png</normal_map>
              <metalness_map>materials/textures/Tethys_Metalness.png</metalness_map>
              <roughness_map>materials/textures/Tethys_Roughness.png</roughness_map>
            </metal>
          </pbr>
          <script>
            <uri>materials/scripts/</uri>
            <uri>materials/textures/</uri>
            <name>tethys/Tethys_Diffuse</name>
          </script>
        </material>
      </visual>
    </link>

    <!-- Vertical fins -->
    <link name="vertical_fins">
      <pose>1.05 0 0 0 0 0</pose>
      <inertial>
        <mass>0.2</mass>
        <inertia>
          <ixx>0.0007924568755</ixx>
          <ixy>-0.0000000002674</ixy>
          <ixz>0.0003978158176</ixz>
          <iyy>0.0010546736475</iyy>
          <iyz>-0.0000000006729</iyz>
          <izz>0.0002633558262</izz>
        </inertia>
      </inertial>

      <collision name="vertical_fin_buoyancy">
        @neutral_buoyancy
      </collision>

      <visual name= "visual">
        <pose>-1.05 0 0 0 0 0</pose>
        <geometry>
          <mesh>
            <uri>meshes/tethys.dae</uri>
            <submesh>
              <name>Fins_vertical</name>
              <center>false</center>
            </submesh>
          </mesh>
        </geometry>
        <material>
          <diffuse>1.0 1.0 1.0</diffuse>
          <specular>1.0 1.0 1.0</specular>
          <pbr>
            <metal>
              <albedo_map>materials/textures/Tethys_Albedo.png</albedo_map>
              <normal_map>materials/textures/Tethys_Normal.png</normal_map>
              <metalness_map>materials/textures/Tethys_Metalness.png</metalness_map>
              <roughness_map>materials/textures/Tethys_Roughness.png</roughness_map>
            </metal>
          </pbr>
          <script>
            <uri>materials/scripts/</uri>
            <uri>materials/textures/</uri>
            <name>tethys/Tethys_Diffuse</name>
          </script>
        </material>
      </visual>
    </link>

    <!-- Propeller -->
    <link name="propeller">
      <pose>1.43162 0 0 0 0 0</pose>
      <inertial>
        <pose>0 0 0 1.570796 0 0</pose>
        <mass>0.09</mass>
        <inertia>
          <ixx>0.000143971303</ixx>
          <ixy>0.000000000008</ixy>
          <ixz>-0.000000000224</ixz>
          <iyy>0.000140915448</iyy>
          <iyz>-0.000025236433</iyz>
          <izz>0.000033571862</izz>
        </inertia>
      </inertial>

      <collision name="propeller_buoyancy">
        @neutral_buoyancy
      </collision>

      <visual name= "visual">
        <pose>-1.43162 0 0 0 0 0</pose>
        <geometry>
          <mesh>
            <uri>meshes/tethys.dae</uri>
            <submesh>
              <name>Prop</name>
              <center>false</center>
            </submesh>
          </mesh>
        </geometry>
        <material>
          <diffuse>1.0 1.0 1.0</diffuse>
          <specular>1.0 1.0 1.0</specular>
          <pbr>
            <metal>
              <albedo_map>materials/textures/Tethys_Albedo.png</albedo_map>
              <normal_map>materials/textures/Tethys_Normal.png</normal_map>
              <metalness_map>materials/textures/Tethys_Metalness.png</metalness_map>
              <roughness_map>materials/textures/Tethys_Roughness.png</roughness_map>
            </metal>
          </pbr>
          <script>
            <uri>materials/scripts/</uri>
            <uri>materials/textures/</uri>
            <name>tethys/Tethys_Diffuse</name>
          </script>
        </material>
      </visual>
    </link>

    <!-- Battery -->
    <!-- No separate collision for battery, because it is inside the vehicle.
         Additional collision requires buoyancy volume recalculation. -->
    <link name="battery">
      <!--TODO: On hold till mesh center adjusted to aft dome, then it will be 0.563, 0, 0.024.-->
      
      <inertial>
        <!-- Non-zero y creates roll. Not fun to tune without actual base link inertia minus battery-->
        <pose>-0.563 0 0 0 0 0</pose>
        <mass>31.7307</mass>
        <inertia>
          <ixx>0.2327</ixx>
          <ixy>0</ixy>
          <ixz>-0.0004</ixz>
          <iyy>1.0930</iyy>
          <iyz>0</iyz>
          <izz>1.0344</izz>
        </inertia>
      </inertial>

      <visual name= "visual">
        <geometry>
          <box>
            <size>0.6489446 0.24638 0.17415</size>
          </box>
        </geometry>
        <material>
          <diffuse>0.0 0.0 1.0 1.0</diffuse>
          <specular>0.0 0.0 1.0 1.0</specular>
        </material>
      </visual>
    </link>

    <link name="buoyancy_engine">
      <!-- TODO: Determine location of buoyancy engine -->
      <pose>0.4 0 0 0 0 0</pose>

      <!-- TODO: Remove inertial and collision

         This link was originally given inertia because Gazebo would segfault
         with links without inertia. To counter this mass, a volume (collision)
         was added, which adds buoyancy.

         Gazebo doesn't have this limitation anymore, so both the inertia and
         collision could be removed. However, it looks like the link's weight
         and buoyancy aren't cancelling each other out precisely at the moment
         (why?), so removing them makes the vehicle unstable.

      -->
      <inertial>
        <pose>0 0 0 0 0 0</pose>
        <mass>0.3</mass>
        <inertia>
          <ixx>0.000143971303</ixx>
          <ixy>0.000000000008</ixy>
          <ixz>-0.000000000224</ixz>
          <iyy>0.000140915448</iyy>
          <iyz>-0.000025236433</iyz>
          <izz>0.000033571862</izz>
        </inertia>
      </inertial>
      <collision name="buoyancy_engine">
        @neutral_buoyancy
      </collision>
    </link>

    <!-- Joints -->
    <!--<joint name="buoyancy_engine_joint" type="fixed">
      <pose>0 0 0 0 0 0</pose>
      <parent>base_link</parent>
      <child>buoyancy_engine</child>
      <namespace>tethys</namespace>
    </joint>-->
    <joint name="horizontal_fins_joint" type="revolute">
      <pose>0 0 0 0 0 0</pose>
      <parent>base_link</parent>
      <child>horizontal_fins</child>
      <axis>
        <xyz>0 1 0</xyz>
        <limit>
          <lower>-0.261799</lower>
          <upper>0.261799</upper>
          <effort>-1</effort>
          <velocity>-1</velocity>
        </limit>
      </axis>
    </joint>

    <joint name="vertical_fins_joint" type="revolute">
      <pose degrees="true">0 0 0   180 0 0</pose>
      <parent>base_link</parent>
      <child>vertical_fins</child>
      <axis>
        <xyz>0 0 1</xyz>
        <limit>
          <lower>-0.261799</lower>
          <upper>0.261799</upper>
          <effort>-1</effort>
          <velocity>-1</velocity>
        </limit>
      </axis>
    </joint>
    
    <joint name="propeller_joint" type="revolute">
      <pose>0 0 0 0 0 0</pose>
      <parent>base_link</parent>
      <child>propeller</child>
      <axis>
        <xyz>1 0 0</xyz>
        <limit>
          <lower>-1e+12</lower>
          <upper>1e+12</upper>
          <effort>1e6</effort>
          <velocity>-1</velocity>
        </limit>
      </axis>
    </joint>

    <!-- positive joint values move mass forward -->
    <joint name="battery_joint" type="prismatic">
      <pose degrees="true">0 0 0   0 0 180</pose>
      <parent>base_link</parent>
      <child>battery</child>
      <axis>
        <xyz>1 0 0</xyz>
        <limit>
          <lower>-0.03</lower>
          <upper>0.03</upper>
          <effort>1e6</effort>
          <velocity>0.0007</velocity>
        </limit>
      </axis>
    </joint>

    <!-- Drop weight -->
    <link name="drop_weight">
      <pose>0.128 0 0 0 0 0</pose>
      <inertial>
        <mass>1</mass>
        <inertia>
          <ixx>0.000143971303</ixx>
          <iyy>0.000140915448</iyy>
          <izz>0.000033571862</izz>
        </inertia>
      </inertial>
    </link>
  </model>
</sdf>
